<?xml version="1.0" encoding="UTF-8"?>
<sdf version='1.9'>
  <model name='aruco_robot' canonical_link='chassis'>
    <pose>0 0 0 0 0 0</pose>   <!--the pose is relative to the world by default-->

    <!--chassis-->
    <link name='chassis'>
        <pose relative_to='__model__'>0.5 0 0.4 0 0 0</pose>
        <inertial> <!--inertial properties of the link mass, inertia matix-->
            <mass>1.14395</mass>
            <inertia>
                <ixx>0.095329</ixx>
                <ixy>0</ixy>
                <ixz>0</ixz>
                <iyy>0.381317</iyy>
                <iyz>0</iyz>
                <izz>0.476646</izz>
            </inertia>
        </inertial>
        <visual name='visual'>
            <geometry>
                <box>
                    <size>3.0 1.8 0.5</size>
                </box>
            </geometry>
            <!--Color of the link-->
            <material>
                <ambient>0.3 0.35 0.4 1</ambient>
                <diffuse>0.3 0.35 0.4 1</diffuse>
                <specular>0.3 0.35 0.4 1</specular>
            </material>
        </visual>
        <collision name='collision'>
            <geometry>
                <box>
                    <size>3.0 1.8 0.5</size>
                </box>
            </geometry>
        </collision>
    </link>

    <!--Left wheel-->
    <link name='left_wheel'>
        <pose relative_to="chassis">-0.5 0.9 0 -1.5707 0 0</pose> <!--angles are in radian-->
        <inertial>
            <mass>1</mass>
            <inertia>
                <ixx>0.043333</ixx>
                <ixy>0</ixy>
                <ixz>0</ixz>
                <iyy>0.043333</iyy>
                <iyz>0</iyz>
                <izz>0.08</izz>
            </inertia>
        </inertial>
        <visual name='visual'>
            <geometry>
                <cylinder>
                    <radius>0.4</radius>
                    <length>0.2</length>
                </cylinder>
            </geometry>
            <material>
                <ambient>0.1 0.1 0.1 1</ambient>
                <diffuse>0.1 0.1 0.1 1</diffuse>
                <specular>0.1 0.1 0.1 1</specular>
            </material>
        </visual>
        <collision name='collision'>
            <geometry>
                <cylinder>
                    <radius>0.4</radius>
                    <length>0.2</length>
                </cylinder>
            </geometry>
        </collision>
    </link>

    <!--The same as left wheel but with different position-->
    <link name='right_wheel'>
        <pose relative_to="chassis">-0.5 -0.9 0 -1.5707 0 0</pose> <!--angles are in radian-->
        <inertial>
            <mass>1</mass>
            <inertia>
                <ixx>0.043333</ixx>
                <ixy>0</ixy>
                <ixz>0</ixz>
                <iyy>0.043333</iyy>
                <iyz>0</iyz>
                <izz>0.08</izz>
            </inertia>
        </inertial>
        <visual name='visual'>
            <geometry>
                <cylinder>
                    <radius>0.4</radius>
                    <length>0.2</length>
                </cylinder>
            </geometry>
            <material>
                <ambient>0.1 0.1 0.1 1</ambient>
                <diffuse>0.1 0.1 0.1 1</diffuse>
                <specular>0.1 0.1 0.1 1</specular>
            </material>
        </visual>
        <collision name='collision'>
            <geometry>
                <cylinder>
                    <radius>0.4</radius>
                    <length>0.2</length>
                </cylinder>
            </geometry>
        </collision>
    </link>

    <!--arbitrary frame-->
    <frame name="caster_frame" attached_to='chassis'>
        <pose>1.2 0 -0.2 0 0 0</pose>
    </frame>

    <!--caster wheel-->
    <link name='caster'>
        <pose relative_to='caster_frame'/>
        <inertial>
            <mass>1</mass>
            <inertia>
                <ixx>0.016</ixx>
                <ixy>0</ixy>
                <ixz>0</ixz>
                <iyy>0.016</iyy>
                <iyz>0</iyz>
                <izz>0.016</izz>
            </inertia>
        </inertial>
        <visual name='visual'>
            <geometry>
                <sphere>
                    <radius>0.2</radius>
                </sphere>
            </geometry>
            <material>
                <ambient>0.0 1 0.0 1</ambient>
                <diffuse>0.0 1 0.0 1</diffuse>
                <specular>0.0 1 0.0 1</specular>
            </material>
        </visual>
        <collision name='collision'>
            <geometry>
                <sphere>
                    <radius>0.2</radius>
                </sphere>
            </geometry>
        </collision>
    </link>

    <!--left wheel joint-->
    <joint name='left_wheel_joint' type='revolute'>
        <pose relative_to='left_wheel'/>
        <parent>chassis</parent>
        <child>left_wheel</child>
        <axis>
            <xyz expressed_in='__model__'>0 1 0</xyz> <!--can be descired to any frame or even arbitrary frames-->
            <limit>
                <lower>-1.79769e+308</lower>    <!--negative infinity-->
                <upper>1.79769e+308</upper>     <!--positive infinity-->
            </limit>
        </axis>
    </joint>

    <!--right wheel joint-->
    <joint name='right_wheel_joint' type='revolute'>
        <pose relative_to='right_wheel'/>
        <parent>chassis</parent>
        <child>right_wheel</child>
        <axis>
            <xyz expressed_in='__model__'>0 1 0</xyz>
            <limit>
                <lower>-1.79769e+308</lower>    <!--negative infinity-->
                <upper>1.79769e+308</upper>     <!--positive infinity-->
            </limit>
        </axis>
    </joint>

    <!--caster wheel joint--> <!--pose defult value is the child-->
    <joint name='caster_wheel' type='ball'>
        <parent>chassis</parent>
        <child>caster</child>
    </joint>

    <!-- ArUco marker sur le dessus du robot -->
    <link name='aruco_marker'>
        <pose relative_to="chassis">0 0 0.3 0 0 0</pose>
        <inertial>
            <mass>0.1</mass>
            <inertia>
                <ixx>0.001</ixx>
                <ixy>0</ixy>
                <ixz>0</ixz>
                <iyy>0.001</iyy>
                <iyz>0</iyz>
                <izz>0.001</izz>
            </inertia>
        </inertial>
        <visual name='aruco_visual'>
            <geometry>
                <plane>
                    <normal>0 0 1</normal>
                    <size>0.7 0.7</size>
                </plane>
            </geometry>
            <material>
                <diffuse>1 1 1 1</diffuse>
                <specular>0.4 0.4 0.4 1</specular>
                <pbr>
                    <metal>
                        <albedo_map>model://arucotag/arucotag.png</albedo_map>
                    </metal>
                </pbr>
            </material>
        </visual>
        <collision name='aruco_collision'>
            <geometry>
                <box>
                    <size>0.7 0.7 0.01</size>
                </box>
            </geometry>
        </collision>
    </link>

    <!-- Joint pour fixer l'ArUco sur le chassis -->
    <joint name='aruco_joint' type='fixed'>
        <parent>chassis</parent>
        <child>aruco_marker</child>
    </joint>

    <!-- Plugin pour contrôler le robot avec cmd_vel -->
    <plugin
      filename="gz-sim-diff-drive-system"
      name="gz::sim::systems::DiffDrive">
      <left_joint>left_wheel_joint</left_joint>
      <right_joint>right_wheel_joint</right_joint>
      <wheel_separation>1.8</wheel_separation>
      <wheel_radius>0.4</wheel_radius>
      <odom_publish_frequency>50</odom_publish_frequency>
      <topic>cmd_vel</topic>
    </plugin>

  </model>
</sdf>
